Workbook

Sheet README
A1: Virat Kohli Career Statistics - Data Collection
A3: One consolidated dataset: 176 records covering Tests, ODIs, T20Is and the IPL (collected 24 Oct 2026).
A5: WHAT IS INSIDE
A6: Stats - the dataset (one row per record). Section says what the record is: Career, Year, Opponent, Dismissal, Batting Position, Innings Context, Match Result.
A7: Data_Dictionary - what every column means.
A8: Sources - where each part of the data came from.
A9: Reconciliation - formula checks that the parts add up to the career totals.
A11: COVERAGE
A12: Career summary for 4 formats | Year-wise runs (Test 2011-2025, ODI 2008-2026, T20I 2010-2024, IPL 2008-2026) | Runs against 18 international teams and 14 IPL teams
A13: Dismissal types | Batting position | Batting first vs chasing | Match result
A15: DATA QUALITY (Data_Quality column)
A16: Exact - read from Statsguru-style screenshots (Test/ODI/T20I career, years, opponents; IPL runs by team; Test position, result, batting-first).
... A22: Test and ODI dismissal counts do not equal innings minus not outs (see Reconciliation). IPL season and team rows have no innings, not-outs or balls faced. Venues are not included. IPL team full names were inferred from short names.

Sheet Stats
A1: Section | B1: Format | C1: Format_Group | D1: Format_Sort | E1: Year | F1: Competition | G1: Opponent | H1: Opponent_Short | I1: Category | J1: Category_Detail | K1: Category_Sort | L1: Matches | M1: Innings | N1: NotOuts | O1: Runs | P1: BallsFaced | Q1: HS_Numeric | R1: HS_NotOut | S1: Hundreds | T1: Fifties | U1: DoubleHundreds | V1: Ducks | W1: Fours | X1: Sixes | Y1: Dismissal_Count | Z1: Average_Reported | AA1: Data_Quality
A2: Career | B2: Test | C2: International | D2: 1 | L2: 123 | M2: 210 | N2: 13 | O2: 9230 | P2: 16608 | Q2: 254 | R2: 1 | S2: 30 | T2: 31 | U2: 7 | V2: 15 | W2: 1027 | X2: 30 | AA2: Exact
A3: Career | B3: ODI | C3: International | D3: 2 | L3: 317 | M3: 305 | N3: 48 | O3: 15109 | P3: 16011 | Q3: 183 | R3: 0 | S3: 55 | T3: 79 | U3: 0 | V3: 19 | W3: 1402 | X3: 181 | AA3: Exact
A4: Career | B4: T20I | C4: International | D4: 3 | L4: 125 | M4: 117 | N4: 31 | O4: 4188 | P4: 3056 | Q4: 122 | R4: 1 | S4: 1 | T4: 38 | U4: 0 | V4: 7 | W4: 369 | X4: 124 | AA4: Exact
A5: Career | B5: IPL | C5: Franchise | D5: 4 | L5: 283 | M5: 275 | N5: 44 | O5: 9336 | P5: 6926 | Q5: 113 | R5: 1 | S5: 9 | T5: 68 | U5: 0 | V5: 12 | W5: 844 | X5: 316 | AA5: CSV
A6: Year | B6: Test | C6: International | D6: 1 | E6: 2011 | L6: 5 | M6: 9 | N6: 0 | O6: 202 | P6: 473 | Q6: 63 | R6: 0 | S6: 0 | T6: 2 | V6: 2 | W6: 15 | X6: 2 | AA6: Exact
A7: Year | B7: Test | C7: International | D7: 1 | E7: 2012 | L7: 9 | M7: 16 | N7: 2 | O7: 689 | P7: 1474 | Q7: 116 | R7: 0 | S7: 3 | T7: 3 | V7: 0 | W7: 89 | X7: 2 | AA7: Exact
A8: Year | B8: Test | C8: International | D8: 1 | E8: 2013 | L8: 8 | M8: 12 | N8: 1 | O8: 616 | P8: 1127 | Q8: 119 | R8: 0 | S8: 2 | T8: 3 | V8: 0 | W8: 73 | X8: 2 | AA8: Exact
A9: Year | B9: Test | C9: International | D9: 1 | E9: 2014 | L9: 10 | M9: 20 | N9: 1 | O9: 847 | P9: 1399 | Q9: 169 | R9: 0 | S9: 4 | T9: 2 | V9: 2 | W9: 101 | X9: 2 | AA9: Exact
A10: Year | B10: Test | C10: International | D10: 1 | E10: 2015 | L10: 9 | M10: 15 | N10: 0 | O10: 640 | P10: 1184 | Q10: 147 | R10: 0 | S10: 2 | T10: 2 | V10: 0 | W10: 74 | X10: 1 | AA10: Exact
A11: Year | B11: Test | C11: International | D11: 1 | E11: 2016 | L11: 12 | M11: 18 | N11: 2 | O11: 1215 | P11: 2011 | Q11: 235 | R11: 0 | S11: 4 | T11: 2 | V11: 0 | W11: 134 | X11: 2 | AA11: Exact
A12: Year | B12: Test | C12: International | D12: 1 | E12: 2017 | L12: 10 | M12: 16 | N12: 2 | O12: 1059 | P12: 1389 | Q12: 243 | R12: 0 | S12: 5 | T12: 1 | V12: 2 | W12: 97 | X12: 6 | AA12: Exact
A13: Year | B13: Test | C13: International | D13: 1 | E13: 2018 | L13: 13 | M13: 24 | N13: 0 | O13: 1322 | P13: 2433 | Q13: 153 | R13: 0 | S13: 5 | T13: 5 | V13: 2 | W13: 144 | X13: 2 | AA13: Exact
A14: Year | B14: Test | C14: International | D14: 1 | E14: 2019 | L14: 8 | M14: 11 | N14: 2 | O14: 612 | P14: 967 | Q14: 254 | R14: 1 | S14: 2 | T14: 2 | V14: 2 | W14: 78 | X14: 3 | AA14: Exact
A15: Year | B15: Test | C15: International | D15: 1 | E15: 2020 | L15: 3 | M15: 6 | N15: 0 | O15: 116 | P15: 283 | Q15: 74 | R15: 0 | S15: 0 | T15: 1 | V15: 0 | W15: 15 | X15: 0 | AA15: Exact
A16: Year | B16: Test | C16: International | D16: 1 | E16: 2021 | L16: 11 | M16: 19 | N16: 0 | O16: 536 | P16: 1216 | Q16: 72 | R16: 0 | S16: 0 | T16: 4 | V16: 4 | W16: 60 | X16: 1 | AA16: Exact
A17: Year | B17: Test | C17: International | D17: 1 | E17: 2022 | L17: 6 | M17: 11 | N17: 1 | O17: 265 | P17: 672 | Q17: 79 | R17: 0 | S17: 0 | T17: 1 | V17: 0 | W17: 33 | X17: 1 | AA17: Exact
... A53: Year | B53: T20I | C53: International | D53: 3 | E53: 2024 | L53: 10 | M53: 10 | N53: 0 | O53: 180 | P53: 151 | Q53: 76 | R53: 0 | S53: 0 | T53: 1 | V53: 3 | W53: 13 | X53: 7 | AA53: Exact
A54: Year | B54: IPL | C54: Franchise | D54: 4 | E54: 2008 | L54: 13 | O54: 165 | Q54: 38 | S54: 0 | T54: 0 | W54: 18 | X54: 4 | AA54: CSV
A55: Year | B55: IPL | C55: Franchise | D55: 4 | E55: 2009 | L55: 16 | O55: 246 | Q55: 50 | S55: 0 | T55: 1 | W55: 22 | X55: 8 | AA55: CSV
A56: Year | B56: IPL | C56: Franchise | D56: 4 | E56: 2010 | L56: 16 | O56: 307 | Q56: 58 | S56: 0 | T56: 1 | W56: 26 | X56: 12 | AA56: CSV
A57: Year | B57: IPL | C57: Franchise | D57: 4 | E57: 2011 | L57: 16 | O57: 557 | Q57: 71 | S57: 0 | T57: 4 | W57: 55 | X57: 16 | AA57: CSV
A58: Year | B58: IPL | C58: Franchise | D58: 4 | E58: 2012 | L58: 16 | O58: 364 | Q58: 73 | S58: 0 | T58: 2 | W58: 33 | X58: 9 | AA58: CSV
A59: Year | B59: IPL | C59: Franchise | D59: 4 | E59: 2013 | L59: 16 | O59: 634 | Q59: 99 | S59: 0 | T59: 6 | W59: 64 | X59: 22 | AA59: CSV
A60: Year | B60: IPL | C60: Franchise | D60: 4 | E60: 2014 | L60: 14 | O60: 359 | Q60: 73 | S60: 0 | T60: 2 | W60: 23 | X60: 16 | AA60: CSV
A61: Year | B61: IPL | C61: Franchise | D61: 4 | E61: 2015 | L61: 16 | O61: 505 | Q61: 82 | S61: 0 | T61: 3 | W61: 35 | X61: 23 | AA61: CSV
A62: Year | B62: IPL | C62: Franchise | D62: 4 | E62: 2016 | L62: 16 | O62: 973 | Q62: 113 | S62: 4 | T62: 7 | W62: 83 | X62: 38 | AA62: CSV
A63: Year | B63: IPL | C63: Franchise | D63: 4 | E63: 2017 | L63: 10 | O63: 308 | Q63: 64 | S63: 0 | T63: 4 | W63: 23 | X63: 11 | AA63: CSV
A64: Year | B64: IPL | C64: Franchise | D64: 4 | E64: 2018 | L64: 14 | O64: 530 | Q64: 92 | S64: 0 | T64: 4 | W64: 52 | X64: 18 | AA64: CSV
A65: Year | B65: IPL | C65: Franchise | D65: 4 | E65: 2019 | L65: 14 | O65: 464 | Q65: 100 | S65: 1 | T65: 2 | W65: 46 | X65: 13 | AA65: CSV
... A72: Year | B72: IPL | C72: Franchise | D72: 4 | E72: 2026 | L72: 16 | O72: 675 | Q72: 105 | S72: 1 | T72: 5 | W72: 73 | X72: 25 | AA72: CSV
A73: Opponent | B73: Test | C73: International | D73: 1 | F73: International | G73: Australia | H73: Australia | L73: 30 | M73: 53 | N73: 2 | O73: 2232 | P73: 4292 | Q73: 186 | R73: 0 | S73: 9 | T73: 5 | V73: 3 | W73: 242 | X73: 7 | AA73: Exact
A74: Opponent | B74: Test | C74: International | D74: 1 | F74: International | G74: Bangladesh | H74: Bangladesh | L74: 8 | M74: 13 | N74: 2 | O74: 536 | P74: 748 | Q74: 204 | R74: 0 | S74: 2 | T74: 0 | V74: 1 | W74: 59 | X74: 2 | AA74: Exact
A75: Opponent | B75: Test | C75: International | D75: 1 | F75: International | G75: England | H75: England | L75: 28 | M75: 50 | N75: 3 | O75: 1991 | P75: 3824 | Q75: 235 | R75: 0 | S75: 5 | T75: 9 | V75: 6 | W75: 235 | X75: 2 | AA75: Exact
A76: Opponent | B76: Test | C76: International | D76: 1 | F76: International | G76: New Zealand | H76: New Zealand | L76: 14 | M76: 27 | N76: 2 | O76: 959 | P76: 1779 | Q76: 211 | R76: 0 | S76: 3 | T76: 4 | V76: 2 | W76: 116 | X76: 4 | AA76: Exact
A77: Opponent | B77: Test | C77: International | D77: 1 | F77: International | G77: South Africa | H77: South Africa | L77: 16 | M77: 28 | N77: 2 | O77: 1408 | P77: 2459 | Q77: 254 | R77: 1 | S77: 3 | T77: 5 | V77: 0 | W77: 184 | X77: 6 | AA77: Exact
A78: Opponent | B78: Test | C78: International | D78: 1 | F78: International | G78: Sri Lanka | H78: Sri Lanka | L78: 11 | M78: 18 | N78: 2 | O78: 1085 | P78: 1589 | Q78: 243 | R78: 0 | S78: 5 | T78: 2 | V78: 1 | W78: 99 | X78: 6 | AA78: Exact
A79: Opponent | B79: Test | C79: International | D79: 1 | F79: International | G79: West Indies | H79: West Indies | L79: 16 | M79: 21 | N79: 0 | O79: 1019 | P79: 1917 | Q79: 200 | R79: 0 | S79: 3 | T79: 6 | V79: 2 | W79: 92 | X79: 3 | AA79: Exact
A80: Opponent | B80: ODI | C80: International | D80: 2 | F80: International | G80: Afghanistan | H80: Afghanistan | L80: 3 | M80: 2 | N80: 1 | O80: 122 | P80: 119 | Q80: 67 | R80: 0 | S80: 0 | T80: 2 | V80: 0 | W80: 11 | X80: 0 | AA80: Exact
A81: Opponent | B81: ODI | C81: International | D81: 2 | F81: International | G81: Australia | H81: Australia | L81: 53 | M81: 51 | N81: 4 | O81: 2525 | P81: 2709 | Q81: 123 | R81: 0 | S81: 8 | T81: 16 | V81: 4 | W81: 219 | X81: 25 | AA81: Exact
...

Sheet Data_Dictionary
A1: Column | B1: Meaning | C1: Used in sections
A2: Section | B2: Type of record | C2: All
A3: Format | B3: Test, ODI, T20I or IPL | C3: All
A4: Format_Group | B4: International or Franchise | C4: All
A5: Format_Sort | B5: Sort order for Format | C5: All
A6: Year | B6: Calendar year (IPL: season) | C6: Year
A7: Competition | B7: International or IPL | C7: Opponent
A8: Opponent | B8: Opposition team | C8: Opponent
A9: Opponent_Short | B9: Short team name as shown at source | C9: Opponent
A10: Category | B10: Dismissal type, batting position, batting first/chasing, or match result | C10: Dismissal, Batting Position, Innings Context, Match Result
A11: Category_Detail | B11: Original label from the source before grouping | C11: Splits
A12: Category_Sort | B12: Sort order for Category | C12: Dismissal and splits
... A28: Data_Quality | B28: Exact, CSV, Web or Estimate | C28: All

Sheet Sources
A1: Data | B1: Source | C1: Quality | D1: Note
A2: Test, ODI, T20I career, year-wise and versus-team tables | B2: Statsguru-style player page screenshots (supplied) | C2: Exact | D2: Totals tie to career figures
A3: Test host country, home/away/neutral | B3: Same screenshots | C3: Exact | D3: Not in the final table
A4: Test batting position, result, batting first/fielding first | B4: Same screenshots | C4: Exact
A5: IPL runs against each bowling team | B5: IPL player page screenshot (supplied) | C5: Exact | D5: 14 teams, total 9,336 runs; full team names inferred
A6: IPL career and season rows | B6: Provided CSV; matches iplrecords.com totals (9,336 runs, 275 innings, 844 fours, 316 sixes) | C6: CSV
A7: T20I dismissal types | B7: https://www.sportskeeda.com/cricket/virat-kohli-t20i-dismissal-modes-overview-how-many-times-bowled-lbw-caught | C7: Web | D7: Caught includes caught behind; total 86
A8: IPL dismissal types | B8: https://iplrecords.com/players/virat-kohli | C8: Web | D8: Caught includes caught and bowled; 5 dismissals not itemized at source
A9: Test and ODI dismissal types | B9: AI-generated text (supplied) | C9: Estimate | D9: Do not match real totals; ODI figures resemble early-2023 data
A10: ODI/T20I/IPL batting position, innings context, match result | B10: AI-generated text (supplied) | C10: Estimate | D10: Lower bound of '~' and '+' values used
A11: ODI chasing check (not used) | B11: https://gulfnews.com/sport/cricket/why-virat-kohli-is-the-chase-master-45-of-his-odi-hundreds-came-in-successful-chases-1.500690174 | C11: Reference | D11: 8,638 runs, 30 hundreds, 45 fifties chasing; conflicts with the estimate row

Sheet Reconciliation
A1: Checks use formulas on the Stats sheet. OK means the parts add up to the career figure.
A3: Format | B3: Career runs | C3: Year-wise runs | D3: Opponent runs | E3: Year diff | F3: Opponent diff | G3: Status
A4: Test | B4: =SUMIFS(Stats!$O:$O,Stats!$A:$A,"Career",Stats!$B:$B,$A4) -> 9230 | C4: =SUMIFS(Stats!$O:$O,Stats!$A:$A,"Year",Stats!$B:$B,$A4) -> 9230 | D4: =SUMIFS(Stats!$O:$O,Stats!$A:$A,"Opponent",Stats!$B:$B,$A4) -> 9230 | E4: =C4-B4 -> 0 | F4: =D4-B4 -> 0 | G4: =IF(AND(E4=0,F4=0),"OK","CHECK") -> OK
A5: ODI | B5: =SUMIFS(Stats!$O:$O,Stats!$A:$A,"Career",Stats!$B:$B,$A5) -> 15109 | C5: =SUMIFS(Stats!$O:$O,Stats!$A:$A,"Year",Stats!$B:$B,$A5) -> 15109 | D5: =SUMIFS(Stats!$O:$O,Stats!$A:$A,"Opponent",Stats!$B:$B,$A5) -> 15109 | E5: =C5-B5 -> 0 | F5: =D5-B5 -> 0 | G5: =IF(AND(E5=0,F5=0),"OK","CHECK") -> OK
A6: T20I | B6: =SUMIFS(Stats!$O:$O,Stats!$A:$A,"Career",Stats!$B:$B,$A6) -> 4188 | C6: =SUMIFS(Stats!$O:$O,Stats!$A:$A,"Year",Stats!$B:$B,$A6) -> 4188 | D6: =SUMIFS(Stats!$O:$O,Stats!$A:$A,"Opponent",Stats!$B:$B,$A6) -> 4188 | E6: =C6-B6 -> 0 | F6: =D6-B6 -> 0 | G6: =IF(AND(E6=0,F6=0),"OK","CHECK") -> OK
A7: IPL | B7: =SUMIFS(Stats!$O:$O,Stats!$A:$A,"Career",Stats!$B:$B,$A7) -> 9336 | C7: =SUMIFS(Stats!$O:$O,Stats!$A:$A,"Year",Stats!$B:$B,$A7) -> 9336 | D7: =SUMIFS(Stats!$O:$O,Stats!$A:$A,"Opponent",Stats!$B:$B,$A7) -> 9336 | E7: =C7-B7 -> 0 | F7: =D7-B7 -> 0 | G7: =IF(AND(E7=0,F7=0),"OK","CHECK") -> OK
A8: Total | B8: =SUM(B4:B7) -> 37863 | C8: =SUM(C4:C7) -> 37863 | D8: =SUM(D4:D7) -> 37863 | E8: =SUM(E4:E7) -> 0 | F8: =SUM(F4:F7) -> 0 | G8: =IF(AND(E8=0,F8=0),"OK","CHECK") -> OK
A10: Format | B10: Career matches | C10: Year-wise matches | D10: Difference | G10: Status
A11: Test | B11: =SUMIFS(Stats!$L:$L,Stats!$A:$A,"Career",Stats!$B:$B,$A11) -> 123 | C11: =SUMIFS(Stats!$L:$L,Stats!$A:$A,"Year",Stats!$B:$B,$A11) -> 123 | D11: =C11-B11 -> 0 | G11: =IF(D11=0,"OK","CHECK") -> OK
A12: ODI | B12: =SUMIFS(Stats!$L:$L,Stats!$A:$A,"Career",Stats!$B:$B,$A12) -> 317 | C12: =SUMIFS(Stats!$L:$L,Stats!$A:$A,"Year",Stats!$B:$B,$A12) -> 317 | D12: =C12-B12 -> 0 | G12: =IF(D12=0,"OK","CHECK") -> OK
A13: T20I | B13: =SUMIFS(Stats!$L:$L,Stats!$A:$A,"Career",Stats!$B:$B,$A13) -> 125 | C13: =SUMIFS(Stats!$L:$L,Stats!$A:$A,"Year",Stats!$B:$B,$A13) -> 125 | D13: =C13-B13 -> 0 | G13: =IF(D13=0,"OK","CHECK") -> OK
A14: IPL | B14: =SUMIFS(Stats!$L:$L,Stats!$A:$A,"Career",Stats!$B:$B,$A14) -> 283 | C14: =SUMIFS(Stats!$L:$L,Stats!$A:$A,"Year",Stats!$B:$B,$A14) -> 283 | D14: =C14-B14 -> 0 | G14: =IF(D14=0,"OK","CHECK") -> OK
A16: Format | B16: Innings minus not outs | C16: Dismissal types total | D16: Difference | E16: Source of dismissals | G16: Status
A17: Test | B17: =SUMIFS(Stats!$M:$M,Stats!$A:$A,"Career",Stats!$B:$B,$A17)-SUMIFS(Stats!$N:$N,Stats!$A:$A,"Career",Stats!$B:$B,$A17) -> 197 | C17: =SUMIFS(Stats!$Y:$Y,Stats!$A:$A,"Dismissal",Stats!$B:$B,$A17) -> 184 | D17: =C17-B17 -> -13 | E17: Estimate | G17: =IF(D17=0,"OK","CHECK") -> CHECK
A18: ODI | B18: =SUMIFS(Stats!$M:$M,Stats!$A:$A,"Career",Stats!$B:$B,$A18)-SUMIFS(Stats!$N:$N,Stats!$A:$A,"Career",Stats!$B:$B,$A18) -> 257 | C18: =SUMIFS(Stats!$Y:$Y,Stats!$A:$A,"Dismissal",Stats!$B:$B,$A18) -> 239 | D18: =C18-B18 -> -18 | E18: Estimate | G18: =IF(D18=0,"OK","CHECK") -> CHECK
A19: T20I | B19: =SUMIFS(Stats!$M:$M,Stats!$A:$A,"Career",Stats!$B:$B,$A19)-SUMIFS(Stats!$N:$N,Stats!$A:$A,"Career",Stats!$B:$B,$A19) -> 86 | C19: =SUMIFS(Stats!$Y:$Y,Stats!$A:$A,"Dismissal",Stats!$B:$B,$A19) -> 86 | D19: =C19-B19 -> 0 | E19: Web | G19: =IF(D19=0,"OK","CHECK") -> OK
A20: IPL | B20: =SUMIFS(Stats!$M:$M,Stats!$A:$A,"Career",Stats!$B:$B,$A20)-SUMIFS(Stats!$N:$N,Stats!$A:$A,"Career",Stats!$B:$B,$A20) -> 231 | C20: =SUMIFS(Stats!$Y:$Y,Stats!$A:$A,"Dismissal",Stats!$B:$B,$A20) -> 231 | D20: =C20-B20 -> 0 | E20: Web | G20: =IF(D20=0,"OK","CHECK") -> OK
